[2025-02-27T21:34:05.080+0000] {local_task_job_runner.py:123} INFO - ::group::Pre task execution logs
[2025-02-27T21:34:05.092+0000] {taskinstance.py:2614} INFO - Dependencies all met for dep_context=non-requeueable deps ti=<TaskInstance: load_and_transform.check_file_exists manual__2025-02-27T21:34:00.844211+00:00 [queued]>
[2025-02-27T21:34:05.100+0000] {taskinstance.py:2614} INFO - Dependencies all met for dep_context=requeueable deps ti=<TaskInstance: load_and_transform.check_file_exists manual__2025-02-27T21:34:00.844211+00:00 [queued]>
[2025-02-27T21:34:05.100+0000] {taskinstance.py:2867} INFO - Starting attempt 1 of 2
[2025-02-27T21:34:05.117+0000] {taskinstance.py:2890} INFO - Executing <Task(GCSObjectExistenceSensor): check_file_exists> on 2025-02-27 21:34:00.844211+00:00
[2025-02-27T21:34:05.125+0000] {standard_task_runner.py:72} INFO - Started process 5852 to run task
[2025-02-27T21:34:05.136+0000] {standard_task_runner.py:104} INFO - Running: ['airflow', 'tasks', 'run', 'load_and_transform', 'check_file_exists', 'manual__2025-02-27T21:34:00.844211+00:00', '--job-id', '14', '--raw', '--subdir', 'DAGS_FOLDER/transformation.py', '--cfg-path', '/tmp/tmppntc3tp9']
[2025-02-27T21:34:05.141+0000] {standard_task_runner.py:105} INFO - Job 14: Subtask check_file_exists
[2025-02-27T21:34:05.215+0000] {task_command.py:467} INFO - Running <TaskInstance: load_and_transform.check_file_exists manual__2025-02-27T21:34:00.844211+00:00 [running]> on host airflow.us-central1-c.c.healthcare-project-452218.internal
[2025-02-27T21:34:05.291+0000] {taskinstance.py:3134} INFO - Exporting env vars: AIRFLOW_CTX_DAG_OWNER='airflow' AIRFLOW_CTX_DAG_ID='load_and_transform' AIRFLOW_CTX_TASK_ID='check_file_exists' AIRFLOW_CTX_EXECUTION_DATE='2025-02-27T21:34:00.844211+00:00' AIRFLOW_CTX_TRY_NUMBER='1' AIRFLOW_CTX_DAG_RUN_ID='manual__2025-02-27T21:34:00.844211+00:00'
[2025-02-27T21:34:05.293+0000] {taskinstance.py:732} INFO - ::endgroup::
[2025-02-27T21:34:05.318+0000] {baseoperator.py:423} WARNING - GCSObjectExistenceSensor.execute cannot be called outside TaskInstance!
[2025-02-27T21:34:05.319+0000] {gcs.py:97} INFO - Sensor checks existence of : bkt-src-global-health-data, global_health_data.csv
[2025-02-27T21:34:05.327+0000] {connection.py:277} WARNING - Connection schemes (type: google_cloud_platform) shall not contain '_' according to RFC3986.
[2025-02-27T21:34:05.328+0000] {base.py:84} INFO - Retrieving connection 'google_cloud_default'
[2025-02-27T21:34:05.329+0000] {credentials_provider.py:409} INFO - Getting connection using `google.auth.default()` since no explicit credentials are provided.
[2025-02-27T21:34:05.427+0000] {base.py:339} INFO - Success criteria met. Exiting.
[2025-02-27T21:34:05.445+0000] {taskinstance.py:341} INFO - ::group::Post task execution logs
[2025-02-27T21:34:05.446+0000] {taskinstance.py:353} INFO - Marking task as SUCCESS. dag_id=load_and_transform, task_id=check_file_exists, run_id=manual__2025-02-27T21:34:00.844211+00:00, execution_date=20250227T213400, start_date=20250227T213405, end_date=20250227T213405
[2025-02-27T21:34:05.510+0000] {local_task_job_runner.py:266} INFO - Task exited with return code 0
[2025-02-27T21:34:05.544+0000] {taskinstance.py:3901} INFO - 1 downstream tasks scheduled from follow-on schedule check
[2025-02-27T21:34:05.550+0000] {local_task_job_runner.py:245} INFO - ::endgroup::
