[2025-02-27T21:43:25.325+0000] {local_task_job_runner.py:123} INFO - ::group::Pre task execution logs
[2025-02-27T21:43:25.338+0000] {taskinstance.py:2614} INFO - Dependencies all met for dep_context=non-requeueable deps ti=<TaskInstance: load_and_transform_view.check_file_exists manual__2025-02-27T21:43:20.172370+00:00 [queued]>
[2025-02-27T21:43:25.345+0000] {taskinstance.py:2614} INFO - Dependencies all met for dep_context=requeueable deps ti=<TaskInstance: load_and_transform_view.check_file_exists manual__2025-02-27T21:43:20.172370+00:00 [queued]>
[2025-02-27T21:43:25.345+0000] {taskinstance.py:2867} INFO - Starting attempt 1 of 2
[2025-02-27T21:43:25.363+0000] {taskinstance.py:2890} INFO - Executing <Task(GCSObjectExistenceSensor): check_file_exists> on 2025-02-27 21:43:20.172370+00:00
[2025-02-27T21:43:25.369+0000] {standard_task_runner.py:72} INFO - Started process 6085 to run task
[2025-02-27T21:43:25.377+0000] {standard_task_runner.py:104} INFO - Running: ['airflow', 'tasks', 'run', 'load_and_transform_view', 'check_file_exists', 'manual__2025-02-27T21:43:20.172370+00:00', '--job-id', '39', '--raw', '--subdir', 'DAGS_FOLDER/finial.py', '--cfg-path', '/tmp/tmp9429up4g']
[2025-02-27T21:43:25.381+0000] {standard_task_runner.py:105} INFO - Job 39: Subtask check_file_exists
[2025-02-27T21:43:25.440+0000] {task_command.py:467} INFO - Running <TaskInstance: load_and_transform_view.check_file_exists manual__2025-02-27T21:43:20.172370+00:00 [running]> on host airflow.us-central1-c.c.healthcare-project-452218.internal
[2025-02-27T21:43:25.514+0000] {taskinstance.py:3134} INFO - Exporting env vars: AIRFLOW_CTX_DAG_OWNER='airflow' AIRFLOW_CTX_DAG_ID='load_and_transform_view' AIRFLOW_CTX_TASK_ID='check_file_exists' AIRFLOW_CTX_EXECUTION_DATE='2025-02-27T21:43:20.172370+00:00' AIRFLOW_CTX_TRY_NUMBER='1' AIRFLOW_CTX_DAG_RUN_ID='manual__2025-02-27T21:43:20.172370+00:00'
[2025-02-27T21:43:25.516+0000] {taskinstance.py:732} INFO - ::endgroup::
[2025-02-27T21:43:25.537+0000] {baseoperator.py:423} WARNING - GCSObjectExistenceSensor.execute cannot be called outside TaskInstance!
[2025-02-27T21:43:25.538+0000] {gcs.py:97} INFO - Sensor checks existence of : bkt-src-global-health-data, global_health_data.csv
[2025-02-27T21:43:25.544+0000] {connection.py:277} WARNING - Connection schemes (type: google_cloud_platform) shall not contain '_' according to RFC3986.
[2025-02-27T21:43:25.545+0000] {base.py:84} INFO - Retrieving connection 'google_cloud_default'
[2025-02-27T21:43:25.546+0000] {credentials_provider.py:409} INFO - Getting connection using `google.auth.default()` since no explicit credentials are provided.
[2025-02-27T21:43:25.621+0000] {base.py:339} INFO - Success criteria met. Exiting.
[2025-02-27T21:43:25.640+0000] {taskinstance.py:341} INFO - ::group::Post task execution logs
[2025-02-27T21:43:25.641+0000] {taskinstance.py:353} INFO - Marking task as SUCCESS. dag_id=load_and_transform_view, task_id=check_file_exists, run_id=manual__2025-02-27T21:43:20.172370+00:00, execution_date=20250227T214320, start_date=20250227T214325, end_date=20250227T214325
[2025-02-27T21:43:25.711+0000] {local_task_job_runner.py:266} INFO - Task exited with return code 0
[2025-02-27T21:43:25.754+0000] {taskinstance.py:3901} INFO - 1 downstream tasks scheduled from follow-on schedule check
[2025-02-27T21:43:25.766+0000] {local_task_job_runner.py:245} INFO - ::endgroup::
