[2025-02-27T21:10:16.411+0000] {local_task_job_runner.py:123} INFO - ::group::Pre task execution logs
[2025-02-27T21:10:16.424+0000] {taskinstance.py:2614} INFO - Dependencies all met for dep_context=non-requeueable deps ti=<TaskInstance: check_load_csv_to_bigquery.check_file_exists manual__2025-02-27T21:10:11.614623+00:00 [queued]>
[2025-02-27T21:10:16.433+0000] {taskinstance.py:2614} INFO - Dependencies all met for dep_context=requeueable deps ti=<TaskInstance: check_load_csv_to_bigquery.check_file_exists manual__2025-02-27T21:10:11.614623+00:00 [queued]>
[2025-02-27T21:10:16.434+0000] {taskinstance.py:2867} INFO - Starting attempt 1 of 2
[2025-02-27T21:10:16.463+0000] {taskinstance.py:2890} INFO - Executing <Task(GCSObjectExistenceSensor): check_file_exists> on 2025-02-27 21:10:11.614623+00:00
[2025-02-27T21:10:16.471+0000] {standard_task_runner.py:72} INFO - Started process 5547 to run task
[2025-02-27T21:10:16.483+0000] {standard_task_runner.py:104} INFO - Running: ['airflow', 'tasks', 'run', 'check_load_csv_to_bigquery', 'check_file_exists', 'manual__2025-02-27T21:10:11.614623+00:00', '--job-id', '12', '--raw', '--subdir', 'DAGS_FOLDER/check_file_load_to_bigquery.py', '--cfg-path', '/tmp/tmpx7jiyyoh']
[2025-02-27T21:10:16.488+0000] {standard_task_runner.py:105} INFO - Job 12: Subtask check_file_exists
[2025-02-27T21:10:16.552+0000] {task_command.py:467} INFO - Running <TaskInstance: check_load_csv_to_bigquery.check_file_exists manual__2025-02-27T21:10:11.614623+00:00 [running]> on host airflow.us-central1-c.c.healthcare-project-452218.internal
[2025-02-27T21:10:16.632+0000] {taskinstance.py:3134} INFO - Exporting env vars: AIRFLOW_CTX_DAG_OWNER='airflow' AIRFLOW_CTX_DAG_ID='check_load_csv_to_bigquery' AIRFLOW_CTX_TASK_ID='check_file_exists' AIRFLOW_CTX_EXECUTION_DATE='2025-02-27T21:10:11.614623+00:00' AIRFLOW_CTX_TRY_NUMBER='1' AIRFLOW_CTX_DAG_RUN_ID='manual__2025-02-27T21:10:11.614623+00:00'
[2025-02-27T21:10:16.633+0000] {taskinstance.py:732} INFO - ::endgroup::
[2025-02-27T21:10:16.657+0000] {baseoperator.py:423} WARNING - GCSObjectExistenceSensor.execute cannot be called outside TaskInstance!
[2025-02-27T21:10:16.658+0000] {gcs.py:97} INFO - Sensor checks existence of : bkt-src-global-health-data, global_health_data.csv
[2025-02-27T21:10:16.664+0000] {connection.py:277} WARNING - Connection schemes (type: google_cloud_platform) shall not contain '_' according to RFC3986.
[2025-02-27T21:10:16.664+0000] {base.py:84} INFO - Retrieving connection 'google_cloud_default'
[2025-02-27T21:10:16.665+0000] {credentials_provider.py:409} INFO - Getting connection using `google.auth.default()` since no explicit credentials are provided.
[2025-02-27T21:10:46.756+0000] {gcs.py:97} INFO - Sensor checks existence of : bkt-src-global-health-data, global_health_data.csv
[2025-02-27T21:10:46.763+0000] {connection.py:277} WARNING - Connection schemes (type: google_cloud_platform) shall not contain '_' according to RFC3986.
[2025-02-27T21:10:46.764+0000] {base.py:84} INFO - Retrieving connection 'google_cloud_default'
[2025-02-27T21:10:46.764+0000] {credentials_provider.py:409} INFO - Getting connection using `google.auth.default()` since no explicit credentials are provided.
[2025-02-27T21:11:16.815+0000] {gcs.py:97} INFO - Sensor checks existence of : bkt-src-global-health-data, global_health_data.csv
[2025-02-27T21:11:16.820+0000] {connection.py:277} WARNING - Connection schemes (type: google_cloud_platform) shall not contain '_' according to RFC3986.
[2025-02-27T21:11:16.820+0000] {base.py:84} INFO - Retrieving connection 'google_cloud_default'
[2025-02-27T21:11:16.820+0000] {credentials_provider.py:409} INFO - Getting connection using `google.auth.default()` since no explicit credentials are provided.
[2025-02-27T21:11:46.882+0000] {gcs.py:97} INFO - Sensor checks existence of : bkt-src-global-health-data, global_health_data.csv
[2025-02-27T21:11:46.885+0000] {connection.py:277} WARNING - Connection schemes (type: google_cloud_platform) shall not contain '_' according to RFC3986.
[2025-02-27T21:11:46.886+0000] {base.py:84} INFO - Retrieving connection 'google_cloud_default'
[2025-02-27T21:11:46.886+0000] {credentials_provider.py:409} INFO - Getting connection using `google.auth.default()` since no explicit credentials are provided.
[2025-02-27T21:12:16.941+0000] {gcs.py:97} INFO - Sensor checks existence of : bkt-src-global-health-data, global_health_data.csv
[2025-02-27T21:12:16.945+0000] {connection.py:277} WARNING - Connection schemes (type: google_cloud_platform) shall not contain '_' according to RFC3986.
[2025-02-27T21:12:16.946+0000] {base.py:84} INFO - Retrieving connection 'google_cloud_default'
[2025-02-27T21:12:16.946+0000] {credentials_provider.py:409} INFO - Getting connection using `google.auth.default()` since no explicit credentials are provided.
[2025-02-27T21:12:46.999+0000] {gcs.py:97} INFO - Sensor checks existence of : bkt-src-global-health-data, global_health_data.csv
[2025-02-27T21:12:47.003+0000] {connection.py:277} WARNING - Connection schemes (type: google_cloud_platform) shall not contain '_' according to RFC3986.
[2025-02-27T21:12:47.003+0000] {base.py:84} INFO - Retrieving connection 'google_cloud_default'
[2025-02-27T21:12:47.004+0000] {credentials_provider.py:409} INFO - Getting connection using `google.auth.default()` since no explicit credentials are provided.
[2025-02-27T21:13:17.054+0000] {gcs.py:97} INFO - Sensor checks existence of : bkt-src-global-health-data, global_health_data.csv
[2025-02-27T21:13:17.060+0000] {connection.py:277} WARNING - Connection schemes (type: google_cloud_platform) shall not contain '_' according to RFC3986.
[2025-02-27T21:13:17.060+0000] {base.py:84} INFO - Retrieving connection 'google_cloud_default'
[2025-02-27T21:13:17.061+0000] {credentials_provider.py:409} INFO - Getting connection using `google.auth.default()` since no explicit credentials are provided.
[2025-02-27T21:13:47.112+0000] {gcs.py:97} INFO - Sensor checks existence of : bkt-src-global-health-data, global_health_data.csv
[2025-02-27T21:13:47.116+0000] {connection.py:277} WARNING - Connection schemes (type: google_cloud_platform) shall not contain '_' according to RFC3986.
[2025-02-27T21:13:47.117+0000] {base.py:84} INFO - Retrieving connection 'google_cloud_default'
[2025-02-27T21:13:47.117+0000] {credentials_provider.py:409} INFO - Getting connection using `google.auth.default()` since no explicit credentials are provided.
[2025-02-27T21:13:47.168+0000] {base.py:339} INFO - Success criteria met. Exiting.
[2025-02-27T21:13:47.195+0000] {taskinstance.py:341} INFO - ::group::Post task execution logs
[2025-02-27T21:13:47.195+0000] {taskinstance.py:353} INFO - Marking task as SUCCESS. dag_id=check_load_csv_to_bigquery, task_id=check_file_exists, run_id=manual__2025-02-27T21:10:11.614623+00:00, execution_date=20250227T211011, start_date=20250227T211016, end_date=20250227T211347
[2025-02-27T21:13:47.256+0000] {local_task_job_runner.py:266} INFO - Task exited with return code 0
[2025-02-27T21:13:47.278+0000] {taskinstance.py:3901} INFO - 1 downstream tasks scheduled from follow-on schedule check
[2025-02-27T21:13:47.284+0000] {local_task_job_runner.py:245} INFO - ::endgroup::
